<?xml version="1.0" encoding="utf-8"?>
<!-- =================================================================================== -->
<!-- |    This document was autogenerated by xacro from hummingbird.xacro              | -->
<!-- |    EDITING THIS FILE BY HAND IS NOT RECOMMENDED                                 | -->
<!-- =================================================================================== -->
<!--
  Copyright 2015 Fadri Furrer, ASL, ETH Zurich, Switzerland
  Copyright 2015 Michael Burri, ASL, ETH Zurich, Switzerland
  Copyright 2015 Mina Kamel, ASL, ETH Zurich, Switzerland
  Copyright 2015 Janosch Nikolic, ASL, ETH Zurich, Switzerland
  Copyright 2015 Markus Achtelik, ASL, ETH Zurich, Switzerland

  Licensed under the Apache License, Version 2.0 (the "License");
  you may not use this file except in compliance with the License.
  You may obtain a copy of the License at

  http://www.apache.org/licenses/LICENSE-2.0

  Unless required by applicable law or agreed to in writing, software
  distributed under the License is distributed on an "AS IS" BASIS,
  WITHOUT WARRANTIES OR CONDITIONS OF ANY KIND, either express or implied.
  See the License for the specific language governing permissions and
  limitations under the License.
-->

<?xml version="1.0" ?>


<robot name="hummingbird">

  <link name="base">
    <visual>
      <origin rpy="0 0 0" xyz="0 0 0"/>
      <geometry>
        <mesh filename="../meshes/hummingbird.dae" scale="1 1 1"/>
      </geometry>
      <material name="blue">
        <color rgba="0.0 0.0 0.8 1.0"/>
      </material>
    </visual>
    <collision>
      <origin rpy="0 0 0" xyz="0 0 0"/>
      <geometry>
        <box size="0.1 0.1 0.12"/>
      </geometry>
    </collision>
  </link>

  <joint name="base_joint" type="fixed">
    <origin rpy="0 0 0" xyz="0 0 0"/>
    <parent link="base"/>
    <child link="base_inertia"/>
  </joint>

  <link name="base_inertia">
    <inertial>
      <mass value="0.68"/>
      <!-- [kg] -->
      <origin xyz="0 0 0"/>
      <inertia ixx="0.007" ixy="0.0" ixz="0.0" iyy="0.007" iyz="0.0" izz="0.012"/>
    </inertial>
  </link>


<!--
	rotor 1: clockwise
-->

  <joint name="rotor_1_joint" type="continuous">
    <origin rpy="0 0 0" xyz="0.17 0 0.01"/>
    <axis xyz="0 0 1"/>
    <limit effort="2000" velocity="838" />
    <dynamics damping="0.0" friction="0.0"/>
    <parent link="base"/>
    <child link="rotor_1"/>
  </joint>

  <link name="rotor_1">
    <inertial>
      <mass value="0.009"/>
      <!-- [kg] -->
      <inertia ixx="1.754999298e-06" ixy="0.0" ixz="0.0" iyy="7.506746997300002e-05" iyz="0.0" izz="7.668746932500001e-05"/>
    </inertial>
    <visual>
      <geometry>
        <mesh filename="../meshes/propeller_cw.dae" scale="0.1 0.1 0.1"/>
        <box size="0.2 0.01 0.005"/>
      </geometry>
    </visual>
    <collision>
      <geometry>
        <cylinder length="0.005" radius="0.1"/>
        <!-- [m] -->
      </geometry>
    </collision>
  </link>


<!--
	rotor 2: counter-clockwise
-->

  <joint name="rotor_2_joint" type="continuous">
    <origin rpy="0 0 0" xyz="0 0.17 0.01"/>
    <axis xyz="0 0 1"/>
    <limit effort="2000" velocity="838" />
    <dynamics damping="0.0" friction="0.0"/>
    <parent link="base"/>
    <child link="rotor_2"/>
  </joint>
  <link name="rotor_2">
    <inertial>
      <mass value="0.009"/>
      <!-- [kg] -->
      <inertia ixx="1.754999298e-06" ixy="0.0" ixz="0.0" iyy="7.506746997300002e-05" iyz="0.0" izz="7.668746932500001e-05"/>
    </inertial>
    <visual>
      <geometry>
        <mesh filename="../meshes/propeller_ccw.dae" scale="0.1 0.1 0.1"/>
        <box size="0.2 0.01 0.005"/>
      </geometry>
    </visual>
    <collision>
      <geometry>
        <cylinder length="0.005" radius="0.1"/>
        <!-- [m] -->
      </geometry>
    </collision>
  </link>

  
<!--
	rotor 3: clockwise
-->

<joint name="rotor_3_joint" type="continuous">
    <origin rpy="0 0 0" xyz="-0.17 0 0.01"/>
    <axis xyz="0 0 1"/>
    <limit effort="2000" velocity="838" />
    <dynamics damping="0.0" friction="0.0"/>
    <parent link="base"/>
    <child link="rotor_3"/>
  </joint>

  <link name="rotor_3">
    <inertial>
      <mass value="0.009"/>
      <!-- [kg] -->
      <inertia ixx="1.754999298e-06" ixy="0.0" ixz="0.0" iyy="7.506746997300002e-05" iyz="0.0" izz="7.668746932500001e-05"/>
    </inertial>
    <visual>
      <geometry>
        <mesh filename="../meshes/propeller_cw.dae" scale="0.1 0.1 0.1"/>
        <box size="0.2 0.01 0.005"/>
      </geometry>
    </visual>
    <collision>
      <geometry>
        <cylinder length="0.005" radius="0.1"/>
        <!-- [m] -->
      </geometry>
    </collision>
  </link>


<!--
	rotor 4: counter-clockwise
-->

  <joint name="rotor_4_joint" type="continuous">
    <origin rpy="0 0 0" xyz="0 -0.17 0.01"/>
    <axis xyz="0 0 1"/>
    <limit effort="2000" velocity="838" />
    <dynamics damping="0.0" friction="0.0"/>
    <parent link="base"/>
    <child link="rotor_4"/>
  </joint>

  <link name="rotor_4">
    <inertial>
      <mass value="0.009"/>
      <!-- [kg] -->
      <inertia ixx="1.754999298e-06" ixy="0.0" ixz="0.0" iyy="7.506746997300002e-05" iyz="0.0" izz="7.668746932500001e-05"/>
    </inertial>
    <visual>
      <geometry>
        <mesh filename="../meshes/propeller_ccw.dae" scale="0.1 0.1 0.1"/>
        <box size="0.2 0.01 0.005"/>
      </geometry>
    </visual>
    <collision>
      <geometry>
        <cylinder length="0.005" radius="0.1"/>
        <!-- [m] -->
      </geometry>
    </collision>
  </link>

</robot>




