<?xml version="1.0" encoding="utf-8"?>
<!-- =================================================================================== -->
<!-- |    This document was autogenerated by xacro from ITM_Quadrocopter.xacro         | -->
<!-- |    EDITING THIS FILE BY HAND IS NOT RECOMMENDED                                 | -->
<!-- =================================================================================== -->
<!--
    ITM_Quadrocopter 2020
    Values from file named "trägheitsmomente_quadrocopter.dat"
-->
<?xml version="1.0" ?>


<robot name="ITM_Quadrocopter">

      <material name="blue">
        <color rgba="0.0 0.0 0.8 1.0"/>
      </material>


  <!-- Base -->
  <link name="base">
    <visual>
      <origin rpy="0 0 0" xyz="-0.14 -0.13 0"/>
      <geometry>
	<mesh filename="../meshes/ITM_Quadrocopter.dae" scale="1 1 1"/>
      <material name="blue"/>
      </geometry>
    </visual>
    <collision>
      <origin rpy="0 0 0" xyz="0 0 0"/>
      <geometry>
	<box size="0.1 0.1 0.27"/>
	<!-- [m] [m] [m] -->
      </geometry>
    </collision>
  </link>

  <joint name="base_joint" type="fixed">
    <origin rpy="0 0 0" xyz="0 0 0"/>
    <parent link="base"/>
    <child link="base_inertia"/>
  </joint>

  <link name="base_inertia">
    <inertial>
      <origin xyz="0 0 0"/>
      <mass value="1.659"/>
      <!-- [kg] -->
      <inertia ixx="6.687e-03" ixy="-2.4e-04" ixz="3.467e-04" iyy="1.01e-02" iyz="1.458e-04" izz="9.96e-03"/>
    </inertial>
  </link>


 
  <!-- 
	rotor 0: counter-clockwise 
  -->
  
<joint name="rotor_0_joint" type="continuous">
    <origin rpy="0 0 0" xyz="0.17104913036744201 -0.17104913036744201 0.071"/>
    <axis xyz="0 0 1"/>
    <limit effort="2000" velocity="838" />
    <parent link="base"/>
    <child link="rotor_0"/>
    <dynamics damping="0.0" friction="0.0"/>
  </joint>

  <link name="rotor_0">
    <inertial>
      <mass value="0.017"/>
      <!-- [kg] -->
      <inertia ixx="3.314998674e-06" ixy="0.0" ixz="0.0" iyy="0.00020412741834900002" iyz="0.0" izz="0.000207187417125"/>
    </inertial>
    <visual>
      <geometry>
	<mesh filename="../meshes/propeller_ccw.dae" scale="0.12 0.12 0.12"/>
	<!-- The propeller meshes have a radius of 1m -->
	<box size="0.24 0.01 0.005"/>
      </geometry>
    </visual>
    <collision>
      <geometry>
	<cylinder length="0.005" radius="0.12"/>
	<!-- [m] -->
      </geometry>
    </collision>
  </link>


 <!-- 
	rotor 1: clockwise 
  -->
  
  <joint name="rotor_1_joint" type="continuous">
    <origin rpy="0 0 0" xyz="0.17104913036744201 0.17104913036744201 0.071"/>
    <axis xyz="0 0 1"/>
    <limit effort="2000" velocity="838" />
    <parent link="base"/>
    <child link="rotor_1"/>
    <dynamics damping="0.0" friction="0.0"/>
  </joint>

  <link name="rotor_1">
    <inertial>
      <mass value="0.017"/>
      <!-- [kg] -->
      <inertia ixx="3.314998674e-06" ixy="0.0" ixz="0.0" iyy="0.00020412741834900002" iyz="0.0" izz="0.000207187417125"/>
    </inertial>
    <visual>
      <geometry>
	<mesh filename="../meshes/propeller_cw.dae" scale="0.12 0.12 0.12"/>
	<!-- The propeller meshes have a radius of 1m -->
	<box size="0.24 0.01 0.005"/>
      </geometry>
    </visual>
    <collision>
      <geometry>
	<cylinder length="0.005" radius="0.12"/>
	<!-- [m] -->
      </geometry>
    </collision>
  </link>



  <!-- 
	rotor 2: counter-clockwise 
  -->
  
  <joint name="rotor_2_joint" type="continuous">
    <origin rpy="0 0 0" xyz="-0.17104913036744201 0.17104913036744201 0.071"/>
    <axis xyz="0 0 1"/>
    <limit effort="2000" velocity="838" />
    <parent link="base"/>
    <child link="rotor_2"/>
    <dynamics damping="0.0" friction="0.0"/>
  </joint>

  <link name="rotor_2">
    <inertial>
      <mass value="0.017"/>
      <!-- [kg] -->
      <inertia ixx="3.314998674e-06" ixy="0.0" ixz="0.0" iyy="0.00020412741834900002" iyz="0.0" izz="0.000207187417125"/>
    </inertial>
    <visual>
      <geometry>
	<mesh filename="../meshes/propeller_ccw.dae" scale="0.12 0.12 0.12"/>
	<!-- The propeller meshes have a radius of 1m -->
	<box size="0.24 0.01 0.005"/>
      </geometry>
    </visual>
    <collision>
      <geometry>
	<cylinder length="0.005" radius="0.12"/>
	<!-- [m] -->
      </geometry>
    </collision>
  </link>


  <!-- 
	rotor 3: clockwise 
  -->
  
  <joint name="rotor_3_joint" type="continuous">
    <origin rpy="0 0 0" xyz="-0.17104913036744201 -0.17104913036744201 0.071"/>
    <axis xyz="0 0 1"/>
    <limit effort="2000" velocity="838" />
    <parent link="base"/>
    <child link="rotor_3"/>
    <dynamics damping="0.0" friction="0.0"/>
  </joint>

  <link name="rotor_3">
    <inertial>
      <mass value="0.017"/>
      <!-- [kg] -->
      <inertia ixx="3.314998674e-06" ixy="0.0" ixz="0.0" iyy="0.00020412741834900002" iyz="0.0" izz="0.000207187417125"/>
    </inertial>
    <visual>
      <geometry>
	<mesh filename="../meshes/propeller_cw.dae" scale="0.12 0.12 0.12"/>
	<!-- The propeller meshes have a radius of 1m -->
	<box size="0.24 0.01 0.005"/>
      </geometry>
    </visual>
    <collision>
      <geometry>
	<cylinder length="0.005" radius="0.12"/>
	<!-- [m] -->
      </geometry>
    </collision>
  </link>

</robot>

 <!-- rotors_simulator gazebo plugin parameters for rotor 1
      <robotNamespace>ITM_Quadcopter</robotNamespace>
      <jointName>rotor_1_joint</jointName>
      <linkName>rotor_1</linkName>
      <turningDirection>cw</turningDirection>
      <timeConstantUp>0.0125</timeConstantUp>
      <timeConstantDown>0.025</timeConstantDown>
      <maxRotVelocity>838</maxRotVelocity>
      <motorConstant>8.54858e-06</motorConstant>
      <momentConstant>0.016</momentConstant>
      <commandSubTopic>gazebo/command/motor_speed</commandSubTopic>
      <motorNumber>1</motorNumber>
      <rotorDragCoefficient>8.06428e-05</rotorDragCoefficient>
      <rollingMomentCoefficient>1e-06</rollingMomentCoefficient>
      <motorSpeedPubTopic>motor_speed/1</motorSpeedPubTopic>
      <rotorVelocitySlowdownSim>10</rotorVelocitySlowdownSim>
    </plugin>
  </gazebo>
  <gazebo reference="rotor_1">
    <material>Gazebo/Red</material>
  </gazebo>
  -->
