<?xml version="1.0" ?>
<!-- =================================================================================== -->
<!-- |    This document was autogenerated by xacro from ITM_Quadrocopter.xacro         | -->
<!-- |    EDITING THIS FILE BY HAND IS NOT RECOMMENDED                                 | -->
<!-- =================================================================================== -->
<!--
    ITM_Quadrocopter 2020
    Values from file named "trägheitsmomente_quadrocopter.dat"
-->
<robot name="ITM_Quadrocopter">
  <!-- [m] -->
  <!-- Following values are not edited because of missing informations -->
  <link name="ITM_Quadcopter/base_link"/>
  <joint name="ITM_Quadcopter/base_joint" type="fixed">
    <origin rpy="0 0 0" xyz="0 0 0"/>
    <parent link="ITM_Quadcopter/base_link"/>
    <child link="ITM_Quadcopter/base_link_inertia"/>
  </joint>
  <link name="ITM_Quadcopter/base_link_inertia">
    <inertial>
      <mass value="1.659"/>
      <!-- [kg] -->
      <origin xyz="0 0 0"/>
      <inertia ixx="6.687e-03" ixy="-2.4e-04" ixz="3.467e-04" iyy="1.01e-02" iyz="1.458e-04" izz="9.96e-03"/>
    </inertial>
    <visual>
      <origin rpy="0 0 0" xyz="0 0 0"/>
      <geometry>
        <mesh filename="../meshes/itm_quadrocopter.dae" scale="1 1 1"/>
      </geometry>
    </visual>
    <collision>
      <origin rpy="0 0 0" xyz="0 0 0"/>
      <geometry>
        <box size="0.1 0.1 0.27"/>
        <!-- [m] [m] [m] -->
      </geometry>
    </collision>
  </link>
  <!-- attach multirotor_base_plugin to the base_link -->
  <gazebo>
    <plugin filename="librotors_gazebo_multirotor_base_plugin.so" name="multirotor_base_plugin">
      <robotNamespace>ITM_Quadcopter</robotNamespace>
      <linkName>ITM_Quadcopter/base_link</linkName>
      <rotorVelocitySlowdownSim>10</rotorVelocitySlowdownSim>
    </plugin>
  </gazebo>


  <joint name="ITM_Quadcopter/rotor_1_joint" type="continuous">
    <origin rpy="0 0 0" xyz="0.17104913036744201 0.17104913036744201 0.071"/>
    <axis xyz="0 0 1"/>
    <!-- TODO(ff): not currently set because it's not yet supported -->
    <!-- <limit effort="2000" velocity="${max_rot_velocity}" /> -->
    <parent link="ITM_Quadcopter/base_link"/>
    <child link="ITM_Quadcopter/rotor_1"/>
  </joint>
  <link name="ITM_Quadcopter/rotor_1">
    <inertial>
      <mass value="0.017"/>
      <!-- [kg] -->
      <inertia ixx="3.314998674e-06" ixy="0.0" ixz="0.0" iyy="0.00020412741834900002" iyz="0.0" izz="0.000207187417125"/>
    </inertial>
    <visual>
      <geometry>
        <mesh filename="../meshes/propeller_cw.dae" scale="0.12 0.12 0.12"/>
        <!-- The propeller meshes have a radius of 1m -->
        <!-- <box size="${2*radius_rotor} 0.01 0.005"/> -->
      </geometry>
    </visual>
    <collision>
      <geometry>
        <cylinder length="0.005" radius="0.12"/>
        <!-- [m] -->
      </geometry>
    </collision>
  </link>
  <gazebo>
    <plugin filename="librotors_gazebo_motor_model.so" name="ITM_Quadcopter_frontleft_motor_model">
      <robotNamespace>ITM_Quadcopter</robotNamespace>
      <jointName>ITM_Quadcopter/rotor_1_joint</jointName>
      <linkName>ITM_Quadcopter/rotor_1</linkName>
      <turningDirection>cw</turningDirection>
      <timeConstantUp>0.0125</timeConstantUp>
      <timeConstantDown>0.025</timeConstantDown>
      <maxRotVelocity>838</maxRotVelocity>
      <motorConstant>8.54858e-06</motorConstant>
      <momentConstant>0.016</momentConstant>
      <commandSubTopic>gazebo/command/motor_speed</commandSubTopic>
      <motorNumber>1</motorNumber>
      <rotorDragCoefficient>8.06428e-05</rotorDragCoefficient>
      <rollingMomentCoefficient>1e-06</rollingMomentCoefficient>
      <motorSpeedPubTopic>motor_speed/1</motorSpeedPubTopic>
      <rotorVelocitySlowdownSim>10</rotorVelocitySlowdownSim>
    </plugin>
  </gazebo>
  <gazebo reference="ITM_Quadcopter/rotor_1">
    <material>Gazebo/Red</material>
  </gazebo>

  <joint name="ITM_Quadcopter/rotor_0_joint" type="continuous">
    <origin rpy="0 0 0" xyz="0.17104913036744201 -0.17104913036744201 0.071"/>
    <axis xyz="0 0 1"/>
    <!-- TODO(ff): not currently set because it's not yet supported -->
    <!-- <limit effort="2000" velocity="${max_rot_velocity}" /> -->
    <parent link="ITM_Quadcopter/base_link"/>
    <child link="ITM_Quadcopter/rotor_0"/>
  </joint>
  <link name="ITM_Quadcopter/rotor_0">
    <inertial>
      <mass value="0.017"/>
      <!-- [kg] -->
      <inertia ixx="3.314998674e-06" ixy="0.0" ixz="0.0" iyy="0.00020412741834900002" iyz="0.0" izz="0.000207187417125"/>
    </inertial>
    <visual>
      <geometry>
        <mesh filename="../meshes/propeller_ccw.dae" scale="0.12 0.12 0.12"/>
        <!-- The propeller meshes have a radius of 1m -->
        <box size="${2*radius_rotor} 0.01 0.005"/>
      </geometry>
    </visual>
    <collision>
      <geometry>
        <cylinder length="0.005" radius="0.12"/>
        <!-- [m] -->
      </geometry>
    </collision>
  </link>
  <gazebo>
    <plugin filename="librotors_gazebo_motor_model.so" name="ITM_Quadcopter_frontright_motor_model">
      <robotNamespace>ITM_Quadcopter</robotNamespace>
      <jointName>ITM_Quadcopter/rotor_0_joint</jointName>
      <linkName>ITM_Quadcopter/rotor_0</linkName>
      <turningDirection>ccw</turningDirection>
      <timeConstantUp>0.0125</timeConstantUp>
      <timeConstantDown>0.025</timeConstantDown>
      <maxRotVelocity>838</maxRotVelocity>
      <motorConstant>8.54858e-06</motorConstant>
      <momentConstant>0.016</momentConstant>
      <commandSubTopic>gazebo/command/motor_speed</commandSubTopic>
      <motorNumber>0</motorNumber>
      <rotorDragCoefficient>8.06428e-05</rotorDragCoefficient>
      <rollingMomentCoefficient>1e-06</rollingMomentCoefficient>
      <motorSpeedPubTopic>motor_speed/0</motorSpeedPubTopic>
      <rotorVelocitySlowdownSim>10</rotorVelocitySlowdownSim>
    </plugin>
  </gazebo>
  <gazebo reference="ITM_Quadcopter/rotor_0">
    <material>Gazebo/Red</material>
  </gazebo>

  <joint name="ITM_Quadcopter/rotor_2_joint" type="continuous">
    <origin rpy="0 0 0" xyz="-0.17104913036744201 0.17104913036744201 0.071"/>
    <axis xyz="0 0 1"/>
    <!-- TODO(ff): not currently set because it's not yet supported -->
    <!-- <limit effort="2000" velocity="${max_rot_velocity}" /> -->
    <parent link="ITM_Quadcopter/base_link"/>
    <child link="ITM_Quadcopter/rotor_2"/>
  </joint>
  <link name="ITM_Quadcopter/rotor_2">
    <inertial>
      <mass value="0.017"/>
      <!-- [kg] -->
      <inertia ixx="3.314998674e-06" ixy="0.0" ixz="0.0" iyy="0.00020412741834900002" iyz="0.0" izz="0.000207187417125"/>
    </inertial>
    <visual>
      <geometry>
        <mesh filename="../meshes/propeller_ccw.dae" scale="0.12 0.12 0.12"/>
        <!-- The propeller meshes have a radius of 1m -->
        <box size="${2*radius_rotor} 0.01 0.005"/>
      </geometry>
    </visual>
    <collision>
      <geometry>
        <cylinder length="0.005" radius="0.12"/>
        <!-- [m] -->
      </geometry>
    </collision>
  </link>
  <gazebo>
    <plugin filename="librotors_gazebo_motor_model.so" name="ITM_Quadcopter_backleft_motor_model">
      <robotNamespace>ITM_Quadcopter</robotNamespace>
      <jointName>ITM_Quadcopter/rotor_2_joint</jointName>
      <linkName>ITM_Quadcopter/rotor_2</linkName>
      <turningDirection>ccw</turningDirection>
      <timeConstantUp>0.0125</timeConstantUp>
      <timeConstantDown>0.025</timeConstantDown>
      <maxRotVelocity>838</maxRotVelocity>
      <motorConstant>8.54858e-06</motorConstant>
      <momentConstant>0.016</momentConstant>
      <commandSubTopic>gazebo/command/motor_speed</commandSubTopic>
      <motorNumber>2</motorNumber>
      <rotorDragCoefficient>8.06428e-05</rotorDragCoefficient>
      <rollingMomentCoefficient>1e-06</rollingMomentCoefficient>
      <motorSpeedPubTopic>motor_speed/2</motorSpeedPubTopic>
      <rotorVelocitySlowdownSim>10</rotorVelocitySlowdownSim>
    </plugin>
  </gazebo>
  <gazebo reference="ITM_Quadcopter/rotor_2">
    <material>Gazebo/Blue</material>
  </gazebo>


  <joint name="ITM_Quadcopter/rotor_3_joint" type="continuous">
    <origin rpy="0 0 0" xyz="-0.17104913036744201 -0.17104913036744201 0.071"/>
    <axis xyz="0 0 1"/>
    <!-- TODO(ff): not currently set because it's not yet supported -->
    <limit effort="2000" velocity="${max_rot_velocity}" />
    <parent link="ITM_Quadcopter/base_link"/>
    <child link="ITM_Quadcopter/rotor_3"/>
  </joint>
  <link name="ITM_Quadcopter/rotor_3">
    <inertial>
      <mass value="0.017"/>
      <!-- [kg] -->
      <inertia ixx="3.314998674e-06" ixy="0.0" ixz="0.0" iyy="0.00020412741834900002" iyz="0.0" izz="0.000207187417125"/>
    </inertial>
    <visual>
      <geometry>
        <mesh filename="package://rotors_description/meshes/propeller_cw.dae" scale="0.12 0.12 0.12"/>
        <!-- The propeller meshes have a radius of 1m -->
        <box size="${2*radius_rotor} 0.01 0.005"/>
      </geometry>
    </visual>
    <collision>
      <geometry>
        <cylinder length="0.005" radius="0.12"/>
        <!-- [m] -->
      </geometry>
    </collision>
  </link>
  <gazebo>
    <plugin filename="librotors_gazebo_motor_model.so" name="ITM_Quadcopter_backright_motor_model">
      <robotNamespace>ITM_Quadcopter</robotNamespace>
      <jointName>ITM_Quadcopter/rotor_3_joint</jointName>
      <linkName>ITM_Quadcopter/rotor_3</linkName>
      <turningDirection>cw</turningDirection>
      <timeConstantUp>0.0125</timeConstantUp>
      <timeConstantDown>0.025</timeConstantDown>
      <maxRotVelocity>838</maxRotVelocity>
      <motorConstant>8.54858e-06</motorConstant>
      <momentConstant>0.016</momentConstant>
      <commandSubTopic>gazebo/command/motor_speed</commandSubTopic>
      <motorNumber>3</motorNumber>
      <rotorDragCoefficient>8.06428e-05</rotorDragCoefficient>
      <rollingMomentCoefficient>1e-06</rollingMomentCoefficient>
      <motorSpeedPubTopic>motor_speed/3</motorSpeedPubTopic>
      <rotorVelocitySlowdownSim>10</rotorVelocitySlowdownSim>
    </plugin>
  </gazebo>
  <gazebo reference="ITM_Quadcopter/rotor_3">
    <material>Gazebo/Blue</material>
  </gazebo>
</robot>

